Workbook

Sheet Cómo usar
A1: Inventario final Nº1 — Hermanas Caradonti
A2: Armado el | B2: 1 de octubre de 2026, con el recorrido físico del local
A6: Qué NO es | B6: No es el inventario completo del local. Faltan 624 items sin revisar, casi todos sin etiqueta: eso lo tiene que hacer la dependienta.
A8: LAS HOJAS
A9: Inventario final
A10: Qué falta por campo
A11: Completar por proveedor
A12: Sin categoría
A13: Altas resueltas
A14: Backlog | B14: 5 objetos que el inventario declaraba y no estaban en el local.
A15: A confirmar | B15: Dudas concretas que necesitan una respuesta humana antes de publicar.
A17: CÓMO SE LLENA
A18: Celdas amarillas | B18: Son las editables. El resto sale del recorrido o del catálogo: no tocarlas acá.
A19: Orden sugerido | B19: 1) Peso por proveedor 2) Categorías de los 25 3) Lead time por proveedor 4) Stock real 5) Fotos 6) Descripciones
A20: Regla de publicación | B20: Un producto se publica cuando está al 100%. La columna "Listo para publicar" lo calcula sola.
A21: Precio | B21: Ya normalizado a pesos con IVA. Los dólares están convertidos a $1.535. El TC vive en la hoja de precios, no acá.

Sheet Inventario final
A1: Inventario final Nº1 — 149 objetos verificados en el local
A2: Columnas amarillas: para completar. Las demás salen del recorrido o del catálogo maestro.
A4: SKU | B4: Nombre | C4: Categoría | D4: Proveedor | E4: Régimen | F4: Código proveedor | G4: Precio final (ARS c/IVA) | H4: Costo (ARS) | I4: Margen % | J4: Stock real contado | K4: Stock declarado (viejo) | L4: Alto cm | M4: Ancho cm | N4: Prof cm | O4: Peso kg | P4: Lead time días | Q4: Reponible | R4: Materiales | S4: Descripción de venta | T4: Archivo de foto | U4: Identificador URL | V4: Ubicación en el local | W4: Zona | X4: Completitud | Y4: Listo para publicar | Z4: Origen | AA4: Nota del recorrido
A5: HC-BAN-001 | B5: Azucarera Salta alpaca metal & cuero chivo #1 - Cremera Salta alpaca metal & cuero chivo #1 - Bandeja Salta rect alpaca metal & cuero chivo #1 | C5: Bandejas | D5: HC AIRES DEL SUR | E5: Disponible | F5: HC/ADS48 | G5: 880000 | H5: 616000 | I5: =IFERROR((G5-H5)/G5,"") -> 0.3 | K5: 1 | U5: azucarera-salta-alpaca-metal-cuero-chivo-1-cremera-salta-alpaca-metal- | V5: Deposito | W5: Depósito | X5: =IFERROR(COUNTA(C5,G5,J5,L5,O5,P5,R5,S5,T5,U5)/10,"") -> 0.3 | Y5: =IF(AND(C5<>"",G5<>"",J5<>"",O5<>"",S5<>"",T5<>""),"SÍ","no") -> no | Z5: recorrido · marcado ESTÁ
A6: HC-BAN-002 | B6: BANDEJA DECO LODHI VASSA 25,5X19X2 CM | C6: Bandejas | D6: HC MISHKA | E6: Disponible | F6: [FAD08TR2614] | G6: 66463 | H6: 22511 | I6: =IFERROR((G6-H6)/G6,"") -> 0.66130027 | J6: 2 | K6: 0 | L6: 2 | M6: 26 | N6: 19 | U6: bandeja-deco-lodhi-vassa-25-5x19x2-cm | W6: Sin ubicación declarada | X6: =IFERROR(COUNTA(C6,G6,J6,L6,O6,P6,R6,S6,T6,U6)/10,"") -> 0.5 | Y6: =IF(AND(C6<>"",G6<>"",J6<>"",O6<>"",S6<>"",T6<>""),"SÍ","no") -> no | Z6: recorrido · marcado ESTÁ | AA6: revusar precio
A7: HC-BAN-003 | B7: Bandeja Chalten Pirex rect. pino y alpaca #1 | C7: Bandejas | D7: HC AIRES DEL SUR | E7: Disponible | F7: HC/ADS16 | G7: 275000 | H7: 192500 | I7: =IFERROR((G7-H7)/G7,"") -> 0.3 | J7: 1 | K7: 1 | U7: bandeja-chalten-pirex-rect-pino-y-alpaca-1 | V7: showroom | W7: Showroom | X7: =IFERROR(COUNTA(C7,G7,J7,L7,O7,P7,R7,S7,T7,U7)/10,"") -> 0.4 | Y7: =IF(AND(C7<>"",G7<>"",J7<>"",O7<>"",S7<>"",T7<>""),"SÍ","no") -> no | Z7: recorrido · marcado ESTÁ
A8: HC-BAN-004 | B8: Bandeja Chalten Pirex rect. pino y alpaca #3 | C8: Bandejas | D8: HC AIRES DEL SUR | E8: Disponible | F8: HC/ADS18 | G8: 335000 | H8: 234500 | I8: =IFERROR((G8-H8)/G8,"") -> 0.3 | J8: 2 | K8: 2 | U8: bandeja-chalten-pirex-rect-pino-y-alpaca-3 | V8: 1 showroom, 1 placard fondo | W8: Showroom + placard | X8: =IFERROR(COUNTA(C8,G8,J8,L8,O8,P8,R8,S8,T8,U8)/10,"") -> 0.4 | Y8: =IF(AND(C8<>"",G8<>"",J8<>"",O8<>"",S8<>"",T8<>""),"SÍ","no") -> no | Z8: recorrido · marcado ESTÁ
A9: HC-BAN-005 | B9: Bandeja Glaciar Bar, alpaca y onyx blanco #2 | C9: Bandejas | D9: HC AIRES DEL SUR | E9: Disponible | F9: HC/ADS19 | G9: 1480000 | H9: 1036000 | I9: =IFERROR((G9-H9)/G9,"") -> 0.3 | J9: 1 | K9: 1 | U9: bandeja-glaciar-bar-alpaca-y-onyx-blanco-2 | V9: deposito arriba | W9: Depósito | X9: =IFERROR(COUNTA(C9,G9,J9,L9,O9,P9,R9,S9,T9,U9)/10,"") -> 0.4 | Y9: =IF(AND(C9<>"",G9<>"",J9<>"",O9<>"",S9<>"",T9<>""),"SÍ","no") -> no | Z9: recorrido · marcado ESTÁ
A10: HC-BAN-006 | B10: Bandeja doble blanca jose luis | C10: Bandejas | D10: OROPEL | E10: Disponible (consignación) | F10: HC/JLC07 | G10: 666120 | H10: 382200 | I10: =IFERROR((G10-H10)/G10,"") -> 0.42622951 | U10: bandeja-doble-blanca-jose-luis | W10: Sin ubicación declarada | X10: =IFERROR(COUNTA(C10,G10,J10,L10,O10,P10,R10,S10,T10,U10)/10,"") -> 0.3 | Y10: =IF(AND(C10<>"",G10<>"",J10<>"",O10<>"",S10<>"",T10<>""),"SÍ","no") -> no | Z10: recorrido · marcado ESTÁ
A11: HC-BAN-007 | B11: Bandeja metalica 73x19 con manijas bordo | C11: Bandejas | D11: HC HUS COMPRADO | E11: Disponible | F11: HC/HUS-COM24 | G11: 165000 | H11: 115500 | I11: =IFERROR((G11-H11)/G11,"") -> 0.3 | K11: 1 bordo | L11: 19 | M11: 73 | U11: bandeja-metalica-73x19-con-manijas-bordo | V11: showroom | W11: Showroom | X11: =IFERROR(COUNTA(C11,G11,J11,L11,O11,P11,R11,S11,T11,U11)/10,"") -> 0.4 | Y11: =IF(AND(C11<>"",G11<>"",J11<>"",O11<>"",S11<>"",T11<>""),"SÍ","no") -> no | Z11: recorrido · marcado ESTÁ
A12: HC-BAN-008 | B12: Bandeja onix negra | C12: Bandejas | D12: HC AIRES DEL SUR | E12: Disponible | F12: HC/ADS04 | G12: 354900 | H12: 273000 | I12: =IFERROR((G12-H12)/G12,"") -> 0.23076923 | K12: 1 HC COMPRADO | U12: bandeja-onix-negra | V12: showroom | W12: Showroom | X12: =IFERROR(COUNTA(C12,G12,J12,L12,O12,P12,R12,S12,T12,U12)/10,"") -> 0.3 | Y12: =IF(AND(C12<>"",G12<>"",J12<>"",O12<>"",S12<>"",T12<>""),"SÍ","no") -> no | Z12: recorrido · marcado ESTÁ
A13: HC-CAN-001 | B13: CANASTA ABAKO MEDIANO - 28 x H28cm | C13: Canastos y cestería | D13: HC DUKAAN | E13: Disponible | F13: [AAA01MU5589] | G13: 218483 | H13: 74002 | I13: =IFERROR((G13-H13)/G13,"") -> 0.66129173 | K13: 0 | L13: 28 | M13: 28 | U13: canasta-abako-mediano-28-x-h28cm | W13: Sin ubicación declarada | X13: =IFERROR(COUNTA(C13,G13,J13,L13,O13,P13,R13,S13,T13,U13)/10,"") -> 0.4 | Y13: =IF(AND(C13<>"",G13<>"",J13<>"",O13<>"",S13<>"",T13<>""),"SÍ","no") -> no | Z13: recorrido · marcado ESTÁ
A14: HC-CAN-002 | B14: CANASTO GRAZALEMA SET X3 | C14: Canastos y cestería | D14: HC DUKAAN | E14: Disponible | F14: [AAA01MU5457] | G14: 444205 | H14: 150456 | I14: =IFERROR((G14-H14)/G14,"") -> 0.66129152 | K14: 0 | U14: canasto-grazalema-set-x3 | W14: Sin ubicación declarada | X14: =IFERROR(COUNTA(C14,G14,J14,L14,O14,P14,R14,S14,T14,U14)/10,"") -> 0.3 | Y14: =IF(AND(C14<>"",G14<>"",J14<>"",O14<>"",S14<>"",T14<>""),"SÍ","no") -> no | Z14: recorrido · marcado ESTÁ
A15: HC-CAN-003 | B15: CANASTO LIANA CHICO | C15: Canastos y cestería | D15: HC SOFI SUAYA | E15: Disponible | F15: HC/CLA1 | G15: 88572 | H15: 30000 | I15: =IFERROR((G15-H15)/G15,"") -> 0.66129251 | K15: 2 | U15: canasto-liana-chico | V15: Showroom | W15: Showroom | X15: =IFERROR(COUNTA(C15,G15,J15,L15,O15,P15,R15,S15,T15,U15)/10,"") -> 0.3 | Y15: =IF(AND(C15<>"",G15<>"",J15<>"",O15<>"",S15<>"",T15<>""),"SÍ","no") -> no | Z15: recorrido · marcado ESTÁ | AA15: con asas y pintado 1 - 4 sin asa y naturales (distinguir) 2- natural chico con asa
A16: HC-DEC-001 | B16: CUADRO PEDRAGLIO 1 | C16: Objetos y deco | D16: HC JESUS NUDOS | E16: Disponible | F16: HC/Obra2 | G16: 600 | H16: 300 | I16: =IFERROR((G16-H16)/G16,"") -> 0.5 | K16: 1 | U16: cuadro-pedraglio-1 | V16: placard fondo caja | W16: Placard fondo | X16: =IFERROR(COUNTA(C16,G16,J16,L16,O16,P16,R16,S16,T16,U16)/10,"") -> 0.3 | Y16: =IF(AND(C16<>"",G16<>"",J16<>"",O16<>"",S16<>"",T16<>""),"SÍ","no") -> no | Z16: recorrido · marcado ESTÁ
A17: HC-DEC-002 | B17: CUADRO PEDRAGLIO 2 | C17: Objetos y deco | D17: HC JESUS NUDOS | E17: Disponible | F17: HC/Obra3 | G17: 600 | H17: 300 | I17: =IFERROR((G17-H17)/G17,"") -> 0.5 | K17: 1 | U17: cuadro-pedraglio-2 | V17: placard fondo caja | W17: Placard fondo | X17: =IFERROR(COUNTA(C17,G17,J17,L17,O17,P17,R17,S17,T17,U17)/10,"") -> 0.3 | Y17: =IF(AND(C17<>"",G17<>"",J17<>"",O17<>"",S17<>"",T17<>""),"SÍ","no") -> no | Z17: recorrido · marcado ESTÁ
A18: HC-DEC-003 | B18: Cuadro chico DANGER | C18: Objetos y deco | D18: LILA HUME (ISA) | E18: Disponible (consignación) | F18: HC/LHD | G18: 340 | H18: 238 | I18: =IFERROR((G18-H18)/G18,"") -> 0.3 | K18: 1 | U18: cuadro-chico-danger | V18: showroom | W18: Showroom | X18: =IFERROR(COUNTA(C18,G18,J18,L18,O18,P18,R18,S18,T18,U18)/10,"") -> 0.3 | Y18: =IF(AND(C18<>"",G18<>"",J18<>"",O18<>"",S18<>"",T18<>""),"SÍ","no") -> no | Z18: recorrido · marcado ESTÁ
A19: HC-DEC-004 | B19: Cuadro grande EXIT | C19: Objetos y deco | D19: LILA HUME (ISA) | E19: Disponible (consignación) | F19: HC/LHEX | G19: 480 | H19: 336 | I19: =IFERROR((G19-H19)/G19,"") -> 0.3 | K19: 1 | U19: cuadro-grande-exit | V19: showroom | W19: Showroom | X19: =IFERROR(COUNTA(C19,G19,J19,L19,O19,P19,R19,S19,T19,U19)/10,"") -> 0.3 | Y19: =IF(AND(C19<>"",G19<>"",J19<>"",O19<>"",S19<>"",T19<>""),"SÍ","no") -> no | Z19: recorrido · marcado ESTÁ
A20: HC-DEC-005 | B20: Cuadros Chicos 35x45 | C20: Objetos y deco | D20: SANTIAGO CARRERA | E20: Disponible | F20: HC/SANTIC02 | G20: 3070000 | H20: 2302500 | I20: =IFERROR((G20-H20)/G20,"") -> 0.25 | K20: 2 | L20: 45 | M20: 35 | U20: cuadros-chicos-35x45 | V20: Showroom | W20: Showroom | X20: =IFERROR(COUNTA(C20,G20,J20,L20,O20,P20,R20,S20,T20,U20)/10,"") -> 0.4 | Y20: =IF(AND(C20<>"",G20<>"",J20<>"",O20<>"",S20<>"",T20<>""),"SÍ","no") -> no | Z20: recorrido · alta resuelta contra el catálogo | AA20: visto como "Cuadro 1 - Santiago del Campo" · USD 2000 x 1535 = 3.070.000, exacto. El proveedor es SANTIAGO CARRERA, no DEL CAMPO · visto en el local como "Cuadro 2 - Santiago del Campo"
A21: HC-DEC-006 | B21: Espejo Mármol Crema/ Carrara D70 | C21: Objetos y deco | D21: LIMO MARMOL | E21: Disponible (consignación) | F21: HC/LIMO03 | G21: 550 | H21: 440 | I21: =IFERROR((G21-H21)/G21,"") -> 0.2 | K21: 1 | U21: espejo-marmol-crema-carrara-d70 | V21: Showroom | W21: Showroom | X21: =IFERROR(COUNTA(C21,G21,J21,L21,O21,P21,R21,S21,T21,U21)/10,"") -> 0.3 | Y21: =IF(AND(C21<>"",G21<>"",J21<>"",O21<>"",S21<>"",T21<>""),"SÍ","no") -> no | Z21: recorrido · marcado ESTÁ
A22: HC-FLO-001 | B22: Florero Glaciar, alpaca y onyx blanco #1 | C22: Floreros y jarrones | D22: HC AIRES DEL SUR | E22: Disponible | F22: HC/ADS27 | G22: 830000 | H22: 581000 | I22: =IFERROR((G22-H22)/G22,"") -> 0.3 | K22: 1 | U22: florero-glaciar-alpaca-y-onyx-blanco-1 | V22: Deposito estanteria | W22: Depósito | X22: =IFERROR(COUNTA(C22,G22,J22,L22,O22,P22,R22,S22,T22,U22)/10,"") -> 0.3 | Y22: =IF(AND(C22<>"",G22<>"",J22<>"",O22<>"",S22<>"",T22<>""),"SÍ","no") -> no | Z22: recorrido · marcado ESTÁ
A23: HC-FLO-002 | B23: Florero Salta Mini Rectangular Onix Blanco #1 | C23: Floreros y jarrones | D23: HC AIRES DEL SUR | E23: Disponible | F23: HC/ADS63 | G23: 310000 | H23: 217000 | I23: =IFERROR((G23-H23)/G23,"") -> 0.3 | U23: florero-salta-mini-rectangular-onix-blanco-1 | W23: Sin ubicación declarada | X23: =IFERROR(COUNTA(C23,G23,J23,L23,O23,P23,R23,S23,T23,U23)/10,"") -> 0.3 | Y23: =IF(AND(C23<>"",G23<>"",J23<>"",O23<>"",S23<>"",T23<>""),"SÍ","no") -> no | Z23: recorrido · marcado ESTÁ
A24: HC-FLO-003 | B24: Florero Salta Mini Rectangular Onix Blanco #2 | C24: Floreros y jarrones | D24: HC AIRES DEL SUR | E24: Disponible | F24: HC/ADS64 | G24: 450000 | H24: 315000 | I24: =IFERROR((G24-H24)/G24,"") -> 0.3 | U24: florero-salta-mini-rectangular-onix-blanco-2 | W24: Sin ubicación declarada | X24: =IFERROR(COUNTA(C24,G24,J24,L24,O24,P24,R24,S24,T24,U24)/10,"") -> 0.3 | Y24: =IF(AND(C24<>"",G24<>"",J24<>"",O24<>"",S24<>"",T24<>""),"SÍ","no") -> no | Z24: recorrido · marcado ESTÁ
A25: HC-FLO-004 | B25: Florero Shiva, alpaca y onyx blanco #1 (5x4x10) | C25: Floreros y jarrones | D25: HC AIRES DEL SUR | E25: Disponible | F25: HC/ADS49 | G25: 396000 | H25: 316800 | I25: =IFERROR((G25-H25)/G25,"") -> 0.2 | J25: 27 | K25: 0 | L25: 10 | M25: 5 | N25: 4 | U25: florero-shiva-alpaca-y-onyx-blanco-1-5x4x10 | W25: Sin ubicación declarada | X25: =IFERROR(COUNTA(C25,G25,J25,L25,O25,P25,R25,S25,T25,U25)/10,"") -> 0.5 | Y25: =IF(AND(C25<>"",G25<>"",J25<>"",O25<>"",S25<>"",T25<>""),"SÍ","no") -> no | Z25: recorrido · marcado ESTÁ | AA25: uno blanco uno rosa
A26: HC-FLO-005 | B26: Florero Shiva, alpaca y onyx blanco #2 (11.5 x 8.5 x 20) | C26: Floreros y jarrones | D26: HC AIRES DEL SUR | E26: Disponible | F26: HC/ADS50 | G26: 733000 | H26: 586400 | I26: =IFERROR((G26-H26)/G26,"") -> 0.2 | K26: 1 | L26: 20 | M26: 12 | N26: 8 | U26: florero-shiva-alpaca-y-onyx-blanco-2-11-5-x-8-5-x-20 | V26: Showroom | W26: Showroom | X26: =IFERROR(COUNTA(C26,G26,J26,L26,O26,P26,R26,S26,T26,U26)/10,"") -> 0.4 | Y26: =IF(AND(C26<>"",G26<>"",J26<>"",O26<>"",S26<>"",T26<>""),"SÍ","no") -> no | Z26: recorrido · marcado ESTÁ
A27: HC-FLO-006 | B27: Florero grande. | C27: Floreros y jarrones | D27: LIMO MARMOL | E27: Disponible (consignación) | F27: HC/LIMO05 | G27: 350 | H27: 280 | I27: =IFERROR((G27-H27)/G27,"") -> 0.2 | K27: 1 | U27: florero-grande | V27: Showroom | W27: Showroom | X27: =IFERROR(COUNTA(C27,G27,J27,L27,O27,P27,R27,S27,T27,U27)/10,"") -> 0.3 | Y27: =IF(AND(C27<>"",G27<>"",J27<>"",O27<>"",S27<>"",T27<>""),"SÍ","no") -> no | Z27: recorrido · marcado ESTÁ
A28: HC-FLO-007 | B28: JARRON ATENEA VIDRIO · · COLOR GRIS · · MEDIDAS: 31 x H34cm | C28: Floreros y jarrones | D28: HC DUKAAN | E28: Disponible | F28: [FAD08GR6660] | G28: 321082 | H28: 108753 | I28: =IFERROR((G28-H28)/G28,"") -> 0.66129213 | J28: 4 | K28: 4 | L28: 34 | M28: 31 | U28: jarron-atenea-vidrio-color-gris-medidas-31-x-h34cm | V28: 1 Showroom, 1 arriba living, 2 deposito | W28: Showroom | X28: =IFERROR(COUNTA(C28,G28,J28,L28,O28,P28,R28,S28,T28,U28)/10,"") -> 0.5 | Y28: =IF(AND(C28<>"",G28<>"",J28<>"",O28<>"",S28<>"",T28<>""),"SÍ","no") -> no | Z28: recorrido · marcado ESTÁ
A29: HC-GEN-001 | B29: AKAI LARGO | D29: TALLER POSIBLE | E29: Disponible (consignación) | F29: HC/COCO01 | G29: 968968 | H29: 616000 | I29: =IFERROR((G29-H29)/G29,"") -> 0.36427209 | K29: 1 | U29: akai-largo | V29: showroom | W29: Showroom | X29: =IFERROR(COUNTA(C29,G29,J29,L29,O29,P29,R29,S29,T29,U29)/10,"") -> 0.2 | Y29: =IF(AND(C29<>"",G29<>"",J29<>"",O29<>"",S29<>"",T29<>""),"SÍ","no") -> no | Z29: recorrido · marcado ESTÁ
A30: HC-GEN-002 | B30: BACKGAMMON | D30: HC SOFI SUAYA | E30: Disponible | F30: HC/BG | G30: 1328580 | H30: 450000 | I30: =IFERROR((G30-H30)/G30,"") -> 0.66129251 | J30: 2 | K30: 2 | U30: backgammon | V30: Placard fondo 1, 1 Deposito estanteria | W30: Placard fondo | X30: =IFERROR(COUNTA(C30,G30,J30,L30,O30,P30,R30,S30,T30,U30)/10,"") -> 0.3 | Y30: =IF(AND(C30<>"",G30<>"",J30<>"",O30<>"",S30<>"",T30<>""),"SÍ","no") -> no | Z30: recorrido · marcado ESTÁ
A31: HC-GEN-003 | B31: Butaca Umbral | D31: HC | E31: Disponible | F31: HC/BU | G31: 2983105 | H31: 1010400 | I31: =IFERROR((G31-H31)/G31,"") -> 0.66129251 | J31: 1 | K31: 1 | U31: butaca-umbral | V31: showroom | W31: Showroom | X31: =IFERROR(COUNTA(C31,G31,J31,L31,O31,P31,R31,S31,T31,U31)/10,"") -> 0.3 | Y31: =IF(AND(C31<>"",G31<>"",J31<>"",O31<>"",S31<>"",T31<>""),"SÍ","no") -> no | Z31: recorrido · marcado ESTÁ
A32: HC-GEN-004 | B32: CABALLITO | D32: FERMOB | E32: Disponible (consignación) | F32: HC/FBCLL | G32: 650 | H32: 552 | I32: =IFERROR((G32-H32)/G32,"") -> 0.15076923 | K32: 1 | U32: caballito | V32: PATIO | W32: Patio | X32: =IFERROR(COUNTA(C32,G32,J32,L32,O32,P32,R32,S32,T32,U32)/10,"") -> 0.2 | Y32: =IF(AND(C32<>"",G32<>"",J32<>"",O32<>"",S32<>"",T32<>""),"SÍ","no") -> no | Z32: recorrido · marcado ESTÁ
A33: HC-GEN-005 | B33: CENICEROS | D33: HC | E33: Disponible | F33: HC/CEN | G33: 206668 | H33: 70000 | I33: =IFERROR((G33-H33)/G33,"") -> 0.66129251 | K33: 1 BLANCO/ 1 NEGRO | U33: ceniceros | V33: showroom | W33: Showroom | X33: =IFERROR(COUNTA(C33,G33,J33,L33,O33,P33,R33,S33,T33,U33)/10,"") -> 0.2 | Y33: =IF(AND(C33<>"",G33<>"",J33<>"",O33<>"",S33<>"",T33<>""),"SÍ","no") -> no | Z33: recorrido · marcado ESTÁ
A34: HC-GEN-006 | B34: Casitas acrilico - chicas | D34: FABIANA BARREDA | E34: Disponible | F34: HC/FABI02 | G34: 347000 | H34: 242900 | I34: =IFERROR((G34-H34)/G34,"") -> 0.3 | J34: 2 | K34: 2 | U34: casitas-acrilico-chicas | V34: showroom | W34: Showroom | X34: =IFERROR(COUNTA(C34,G34,J34,L34,O34,P34,R34,S34,T34,U34)/10,"") -> 0.3 | Y34: =IF(AND(C34<>"",G34<>"",J34<>"",O34<>"",S34<>"",T34<>""),"SÍ","no") -> no | Z34: recorrido · marcado ESTÁ
A35: HC-GEN-007 | B35: Casitas acrilicos - grandes | D35: FABIANA BARREDA | E35: Disponible | F35: HC/FABI01 | G35: 629200 | H35: 400000 | I35: =IFERROR((G35-H35)/G35,"") -> 0.36427209 | J35: 1 | K35: 1 | U35: casitas-acrilicos-grandes | W35: Sin ubicación declarada | X35: =IFERROR(COUNTA(C35,G35,J35,L35,O35,P35,R35,S35,T35,U35)/10,"") -> 0.3 | Y35: =IF(AND(C35<>"",G35<>"",J35<>"",O35<>"",S35<>"",T35<>""),"SÍ","no") -> no | Z35: recorrido · marcado ESTÁ
A36: HC-GEN-008 | B36: Cilindro largo (78x18diam) | D36: CSALOM ATELIER | E36: Disponible | F36: HC/CSCL | G36: 845000 | H36: 650000 | I36: =IFERROR((G36-H36)/G36,"") -> 0.23076923 | K36: 1 | L36: 18 | M36: 78 | U36: cilindro-largo-78x18diam | V36: Showroom | W36: Showroom | X36: =IFERROR(COUNTA(C36,G36,J36,L36,O36,P36,R36,S36,T36,U36)/10,"") -> 0.3 | Y36: =IF(AND(C36<>"",G36<>"",J36<>"",O36<>"",S36<>"",T36<>""),"SÍ","no") -> no | Z36: recorrido · marcado ESTÁ
A37: HC-GEN-009 | B37: Cilindro mediano (58x18diam) | D37: CSALOM ATELIER | E37: Disponible | F37: HC/CSCM | G37: 715000 | H37: 550000 | I37: =IFERROR((G37-H37)/G37,"") -> 0.23076923 | J37: 1 | K37: 1 | L37: 18 | M37: 58 | U37: cilindro-mediano-58x18diam | V37: Showroom | W37: Showroom | X37: =IFERROR(COUNTA(C37,G37,J37,L37,O37,P37,R37,S37,T37,U37)/10,"") -> 0.4 | Y37: =IF(AND(C37<>"",G37<>"",J37<>"",O37<>"",S37<>"",T37<>""),"SÍ","no") -> no | Z37: recorrido · marcado ESTÁ
A38: HC-GEN-010 | B38: Cojin Yana Camino blanco y negro 30X45 | D38: HC PAIS TEXTIL PERU | E38: Disponible | F38: HC/PT35 | G38: 112 | H38: 58330 | I38: =IFERROR((G38-H38)/G38,"") -> -519.80357 | L38: 45 | M38: 30 | U38: cojin-yana-camino-blanco-y-negro-30x45 | W38: Sin ubicación declarada | X38: =IFERROR(COUNTA(C38,G38,J38,L38,O38,P38,R38,S38,T38,U38)/10,"") -> 0.3 | Y38: =IF(AND(C38<>"",G38<>"",J38<>"",O38<>"",S38<>"",T38<>""),"SÍ","no") -> no | Z38: recorrido · marcado ESTÁ
A39: HC-GEN-011 | B39: Cojin Yana alpaca y algodón con flecos 50X50 | D39: HC PAIS TEXTIL PERU | E39: Disponible | F39: HC/PT36 | G39: 139 | H39: 72145 | I39: =IFERROR((G39-H39)/G39,"") -> -518.02878 | L39: 50 | M39: 50 | U39: cojin-yana-alpaca-y-algodon-con-flecos-50x50 | W39: Sin ubicación declarada | X39: =IFERROR(COUNTA(C39,G39,J39,L39,O39,P39,R39,S39,T39,U39)/10,"") -> 0.3 | Y39: =IF(AND(C39<>"",G39<>"",J39<>"",O39<>"",S39<>"",T39<>""),"SÍ","no") -> no | Z39: recorrido · marcado ESTÁ
A40: HC-GEN-012 | B40: Cojin Yana block blanco y negro 30X45 | D40: HC PAIS TEXTIL PERU | E40: Disponible | F40: HC/PT33 | G40: 112 | H40: 58330 | I40: =IFERROR((G40-H40)/G40,"") -> -519.80357 | L40: 45 | M40: 30 | U40: cojin-yana-block-blanco-y-negro-30x45 | W40: Sin ubicación declarada | X40: =IFERROR(COUNTA(C40,G40,J40,L40,O40,P40,R40,S40,T40,U40)/10,"") -> 0.3 | Y40: =IF(AND(C40<>"",G40<>"",J40<>"",O40<>"",S40<>"",T40<>""),"SÍ","no") -> no | Z40: recorrido · marcado ESTÁ
A41: HC-GEN-013 | B41: Cojin Yana rayas verticales blanco y negro 30X45 | D41: HC PAIS TEXTIL PERU | E41: Disponible | F41: HC/PT34 | G41: 112 | H41: 58330 | I41: =IFERROR((G41-H41)/G41,"") -> -519.80357 | L41: 45 | M41: 30 | U41: cojin-yana-rayas-verticales-blanco-y-negro-30x45 | W41: Sin ubicación declarada | X41: =IFERROR(COUNTA(C41,G41,J41,L41,O41,P41,R41,S41,T41,U41)/10,"") -> 0.3 | Y41: =IF(AND(C41<>"",G41<>"",J41<>"",O41<>"",S41<>"",T41<>""),"SÍ","no") -> no | Z41: recorrido · marcado ESTÁ
...

Sheet Qué falta por campo
A1: Qué falta para que estos 149 se puedan publicar
A2: Ordenado por cuántos productos bloquea. Los primeros cinco bloquean los 149 por igual: son cinco tareas, no 149 problemas.
A4: Campo | B4: Completos | C4: Faltan | D4: Bloquea publicar | E4: Quién lo resuelve | F4: Cómo
A5: Peso kg | B5: =COUNTA('Inventario final'!O5:O153) -> 0 | C5: =149-B5 -> 149 | D5: SÍ | E5: Las socias / los proveedores | F5: Es el dato que bloquea el checkout: sin peso Tiendanube no cotiza envío. Se completa por proveedor, no de a uno.
A6: Foto | B6: =COUNTA('Inventario final'!T5:T153) -> 0 | C6: =149-B6 -> 149 | D6: SÍ | E6: Habitante Studio | F6: Pedir la carpeta HC HOME de Dropbox copiada a Drive. Convención de nombres: SKU-1.jpg.
A7: Descripción de venta | B7: =COUNTA('Inventario final'!S5:S153) -> 0 | C7: =149-B7 -> 149 | D7: SÍ | E7: Nosotros | F7: Con el documento de voz y textos ya cerrado. 149 textos cortos, se puede hacer por lote y categoría.
A8: Lead time días | B8: =COUNTA('Inventario final'!P5:P153) -> 0 | C8: =149-B8 -> 149 | D8: no | E8: Los proveedores | F8: Atributo del proveedor. 28 proveedores, 5 cubren 88 de los 149.
A9: Materiales | B9: =COUNTA('Inventario final'!R5:R153) -> 0 | C9: =149-B9 -> 149 | D9: no | E9: Las socias | F9: Necesario para la ficha, no para publicar.
A10: Reponible | B10: =COUNTA('Inventario final'!Q5:Q153) -> 0 | C10: =149-B10 -> 149 | D10: no | E10: Las socias | F10: Define si el stock va vacío (infinito) o con número en Tiendanube.
A11: Medidas | B11: =COUNTA('Inventario final'!M5:M153) -> 32 | C11: =149-B11 -> 117 | D11: no | E11: Medir en el local | F11: 117 sin medidas. Alto/ancho/prof van en columnas separadas para Tiendanube.
A12: Stock real contado | B12: =COUNTA('Inventario final'!J5:J153) -> 72 | C12: =149-B12 -> 77 | D12: SÍ | E12: El recorrido | F12: Esta pasada registró presencia, no cantidad. Decisión del 24/9: primero saber qué está.
A13: Categoría | B13: =COUNTA('Inventario final'!C5:C153) -> 124 | C13: =149-B13 -> 25 | D13: SÍ | E13: Las socias | F13: 25 sin categoría, con sugerencia en su propia hoja.
A14: Precio | B14: =COUNTA('Inventario final'!G5:G153) -> 148 | C14: =149-B14 -> 1 | D14: SÍ | E14: Las socias | F14: Sólo 1 producto sin precio.
A16: Productos listos para publicar hoy | B16: =COUNTIF('Inventario final'!Y5:Y153,"SÍ") -> 0
A17: Completitud promedio | B17: =AVERAGE('Inventario final'!X5:X153) -> 0.35234899
A19: Valor de lista del inventario verificado (1 unidad por SKU) | B19: =SUM('Inventario final'!G5:G153) -> 58375365
A20: Es valor de lista, no de stock: la cantidad real todavía no se contó.

Sheet Completar por proveedor
A1: Peso y lead time se completan acá, no producto por producto
A2: Principio acordado en la primera reunión: lead time, capacidad y reposición son atributos del proveedor. 28 proveedores cubren los 149 productos.
A4: Proveedor | B4: Productos | C4: % del inventario | D4: Régimen que usa | E4: Lead time días | F4: Reponible | G4: Contacto | H4: Peso: cómo lo informan
A5: HC KBB | B5: 36 | C5: =B5/149 -> 0.24161074 | D5: Disponible
A6: HC SOFI SUAYA | B6: 18 | C6: =B6/149 -> 0.12080537 | D6: Disponible
A7: HC AIRES DEL SUR | B7: 17 | C7: =B7/149 -> 0.11409396 | D7: Disponible
A8: FERMOB | B8: 10 | C8: =B8/149 -> 0.067114094 | D8: Disponible (consignación)
A9: HC | B9: 7 | C9: =B9/149 -> 0.046979866 | D9: Disponible
A10: HC PAIS TEXTIL PERU | B10: 7 | C10: =B10/149 -> 0.046979866 | D10: Disponible
A11: HC DUKAAN | B11: 6 | C11: =B11/149 -> 0.040268456 | D11: Disponible
A12: LIMO MARMOL | B12: 6 | C12: =B12/149 -> 0.040268456 | D12: Disponible · Disponible (consignación)
A13: HC HUS COMPRADO | B13: 4 | C13: =B13/149 -> 0.026845638 | D13: Disponible
A14: HC MISHKA | B14: 3 | C14: =B14/149 -> 0.020134228 | D14: Disponible
A15: HC JESUS NUDOS | B15: 3 | C15: =B15/149 -> 0.020134228 | D15: Disponible
A16: CSALOM ATELIER | B16: 3 | C16: =B16/149 -> 0.020134228 | D16: Disponible
... A32: SIXTA | B32: 1 | C32: =B32/149 -> 0.0067114094 | D32: Disponible (consignación)
A34: Suma de control | B34: =SUM(B5:B32) -> 149 | D34: Tiene que dar 149

Sheet Sin categoría
A1: 25 productos sin categoría
A2: La columna "Mi sugerencia" es inferencia mía a partir del nombre y el proveedor, no un dato. Aceptar o cambiar en la columna amarilla.
A4: SKU | B4: Nombre | C4: Proveedor | D4: Precio | E4: Mi sugerencia | F4: Categoría definitiva
A5: HC-GEN-001 | B5: AKAI LARGO | C5: TALLER POSIBLE | D5: 968968 | E5: Muebles
A6: HC-GEN-002 | B6: BACKGAMMON | C6: HC SOFI SUAYA | D6: 1328580 | E6: Objetos y deco
A7: HC-GEN-003 | B7: Butaca Umbral | C7: HC | D7: 2983105 | E7: Muebles
A8: HC-GEN-004 | B8: CABALLITO | C8: FERMOB | D8: 650 | E8: Objetos y deco
A9: HC-GEN-005 | B9: CENICEROS | C9: HC | D9: 206668 | E9: Objetos y deco
A10: HC-GEN-006 | B10: Casitas acrilico - chicas | C10: FABIANA BARREDA | D10: 347000 | E10: Objetos y deco
A11: HC-GEN-007 | B11: Casitas acrilicos - grandes | C11: FABIANA BARREDA | D11: 629200 | E11: Objetos y deco
A12: HC-GEN-008 | B12: Cilindro largo (78x18diam) | C12: CSALOM ATELIER | D12: 845000 | E12: Muebles
A13: HC-GEN-009 | B13: Cilindro mediano (58x18diam) | C13: CSALOM ATELIER | D13: 715000 | E13: Muebles
A14: HC-GEN-010 | B14: Cojin Yana Camino blanco y negro 30X45 | C14: HC PAIS TEXTIL PERU | D14: 112 | E14: Textiles
A15: HC-GEN-011 | B15: Cojin Yana alpaca y algodón con flecos 50X50 | C15: HC PAIS TEXTIL PERU | D15: 139 | E15: Textiles
A16: HC-GEN-012 | B16: Cojin Yana block blanco y negro 30X45 | C16: HC PAIS TEXTIL PERU | D16: 112 | E16: Textiles
... A29: HC-GEN-025 | B29: libro Bordeu | C29: HC DIAZ ORTIZ | D29: 100000 | E29: Libros

Sheet Altas resueltas
A1: Objetos dados de alta como "nuevos" que ya estaban en el catálogo
A2: Nueve de los quince. El local y el catálogo usan nombres distintos para la misma cosa; el precio de la etiqueta es lo que permite emparejarlos.
A4: Como se lo vio en el local | B4: Etiqueta | C4: SKU del catálogo | D4: Nombre en el catálogo | E4: Por qué es el mismo
A5: banco pelota | B5: precio 1967000 | C5: I181 | D5: RUFFO PELOTA | E5: precio 1.967.000 vs 1.966.250
A6: mesa ola mop | B6: 1926000 + iva | C6: I722 | D6: Mesa OLA modificada (100x60x45h) | E6: 1.926.000 + IVA = 2.330.460 vs 2.329.444
A7: Cuadro 1 - Santiago del Campo | B7: USD 2000 | C7: I182 | D7: Cuadros Chicos 35x45 | E7: USD 2000 x 1535 = 3.070.000, exacto. El proveedor es SANTIAGO CARRERA, no DEL CAMPO
A8: Cuadro 2 - Santiago del Campo | B8: 2000 usd | C8: I182 | D8: Cuadros Chicos 35x45 | E8: segunda unidad del mismo SKU (stock declarado 2)
A9: Libro - El romance vestido - Agustina Bothlink | C9: I408 | D9: Romance del vestido. | E9: "Romance del vestido.", HC DIAZ ORTIZ
A10: mesa arrime - madera negra | B10: 1342 usd | C10: I087 | D10: MESA DE APOYO (MADERA ROBLE NEGRO) | E10: precio 1342 exacto; confirma que 1342 era USD
A11: Libro Toit du Monde - Lars Miller | B11: sin etiquetar | C11: I085 | D11: Tuit du monde | E11: "Tuit du monde" es el mismo libro mal tipeado; Lars Muller es la editorial
A12: Libro Jorge Macchi - Music stand still | C12: I224 | D12: Music Stands Stills | E12: "Music Stands Stills", HC KBB
A13: Libro Enlargue - Diego Bianchi | B13: etiqueta: - | C13: I219 | D13: Enlarge | E13: "Enlarge"; ese SKU ya estaba marcado ESTÁ, asi que esta alta es redundante
A15: Cinco de los quince sí eran nuevos y están en el inventario con el origen "NUEVO".
A16: Uno quedó dudoso y está en la hoja "A confirmar".

Sheet Backlog
A1: Declarados por el inventario y no encontrados en el local
A2: No se descartan: quedan guardados. Hay que decidir si se reponen, si se buscan de nuevo o si se dan de baja.
A4: SKU viejo | B4: Nombre | C4: Proveedor | D4: Precio | E4: Stock declarado | F4: Ubicación declarada | G4: Qué hacer
A5: I023 | B5: SILLON UMBRAL CUERO PELO MARRON CLARO - 1 ESTRUCTURA CLARA, 1 ESTRUCTURA NEGRA | C5: HC | D5: 3129544 | E5: 2 | F5: Showroom
A6: I024 | B6: SILLON UMBRAL CUERO PELO MARRON OSCURO TEXTURADO 1 ESTRUCTURA NEGRA | C6: HC | D6: 3129544 | E6: 1 | F6: Showroom
A7: I082 | B7: Switzerlarch: Bank and Bastion | C7: HC KBB | D7: 21000 | E7: 1 | F7: SHOWROOM
A8: I144 | B8: CANASTOS LIANA MEDIANO | C8: HC SOFI SUAYA | D8: 177144 | E8: 1 | F8: Showroom
A9: I734 | B9: Mesa mármol Rosa Portugal D35x45 | C9: LIMO MARMOL | D9: 976 | E9: 0

Sheet A confirmar
A1: Preguntas que necesitan una respuesta humana
A2: Ninguna de estas la puedo resolver mirando datos. Están ordenadas por lo que bloquean.
A4: # | B4: Qué | C4: Por qué importa | D4: A quién | E4: Respuesta
A5: 1 | B5: Peso de los productos, al menos un rango por proveedor | C5: Sin peso Tiendanube no cotiza envío. Es el único dato que impide cobrar. | D5: Socias / proveedores
A6: 2 | B6: La carpeta HC HOME de Dropbox copiada a Google Drive | C6: Sin fotos no hay página de producto. Es el segundo bloqueante. | D6: Habitante Studio
A7: 3 | B7: ¿"mesa saporo redonda 45x40" es la Mesa oval saporo L.120 (I640)? | C7: La L.80 (I415) ya está marcada aparte. Si no es ninguna, es un producto nuevo. | D7: Quien recorrió
A8: 4 | B8: La etiqueta de la mesa de mármol rosa decía 88000000 | C8: Es un precio imposible. ¿Son $880.000 o $8.800.000? La del catálogo (D35x45) fue a backlog y esta es otra medida. | D8: Socias
A9: 5 | B9: "mika tanila" a $35.000: ¿qué libro es? | C9: El libro de $35.000 del catálogo (Bouroullec) ya está marcado aparte, así que este es otro. | D9: Socias / HC KBB
A10: 6 | B10: Banqueta Bar a $346.000 y Lámpara Mesa LED a $129.000: ¿de quién son? | C10: Son productos nuevos sin proveedor. Sin proveedor no hay lead time ni régimen. | D10: Socias
A11: 7 | B11: Santiago Carrera y Santiago del Campo son dos proveedores distintos | C11: Los cuadros son de Carrera; los muebles, de Del Campo. Se confundieron en el recorrido y en el cruce de septiembre. | D11: Confirmar con socias
A12: 8 | B12: ¿Qué sets se venden juntos y qué piezas sueltas? | C12: Hay sets y piezas como productos separados. Agrupar variantes DESPUÉS de importar obliga a borrar productos y perder las URLs. | D12: Socias
A13: 9 | B13: Los 3 objetos que existen con stock declarado 0 | C13: Dos Frascos EGG y una manta: están en el local y el inventario decía que no. ¿Se venden? | D13: Socias
A14: 10 | B14: El SILLON UMBRAL CUERO VACA: el inventario declara 2 y se contó 1 | C14: Es la única discrepancia real de cantidad de todo el recorrido. | D14: Quien recorrió
